Sun Oct 20 21:20:26 2019: [unset]:_pmi_alps_sync:alps response not OKAY
Sun Oct 20 21:20:26 2019: [unset]:_pmiu_daemon:_pmi_alps_sync failed 
Sun Oct 20 21:20:26 2019: [PE_0]:_pmi_daemon_barrier:PE pipe read failed from daemon errno = Success
Sun Oct 20 21:20:26 2019: [PE_0]:_pmi_init:_pmi_daemon_barrier returned -1
Traceback (most recent call last):
  File "RNN_test.py", line 50, in <module>
    model = torch.load('rnn.model')
  File "/mnt/bwpy/single/usr/lib/python3.5/site-packages/torch/serialization.py", line 358, in load
    return _load(f, map_location, pickle_module)
  File "/mnt/bwpy/single/usr/lib/python3.5/site-packages/torch/serialization.py", line 542, in _load
    result = unpickler.load()
  File "/mnt/bwpy/single/usr/lib/python3.5/site-packages/torch/serialization.py", line 508, in persistent_load
    data_type(size), location)
  File "/mnt/bwpy/single/usr/lib/python3.5/site-packages/torch/serialization.py", line 104, in default_restore_location
    result = fn(storage, location)
  File "/mnt/bwpy/single/usr/lib/python3.5/site-packages/torch/serialization.py", line 86, in _cuda_deserialize
    return obj.cuda(device)
  File "/mnt/bwpy/single/usr/lib/python3.5/site-packages/torch/_utils.py", line 76, in _cuda
    return new_type(self.size()).copy_(self, non_blocking)
  File "/mnt/bwpy/single/usr/lib/python3.5/site-packages/torch/cuda/__init__.py", line 495, in _lazy_new
    return super(_CudaBase, cls).__new__(cls, *args, **kwargs)
RuntimeError: CUDA error: all CUDA-capable devices are busy or unavailable
Sun Oct 20 21:24:39 2019: [unset]:_pmi_alps_sync:alps response not OKAY
Sun Oct 20 21:24:39 2019: [unset]:_pmiu_daemon:_pmi_alps_sync failed 
Sun Oct 20 21:24:39 2019: [PE_0]:_pmi_daemon_barrier:PE pipe read failed from daemon errno = Success
Sun Oct 20 21:24:39 2019: [PE_0]:_pmi_init:_pmi_daemon_barrier returned -1
Traceback (most recent call last):
  File "RNN_test.py", line 50, in <module>
    model = torch.load('rnn.model')
  File "/mnt/bwpy/single/usr/lib/python3.5/site-packages/torch/serialization.py", line 358, in load
    return _load(f, map_location, pickle_module)
  File "/mnt/bwpy/single/usr/lib/python3.5/site-packages/torch/serialization.py", line 542, in _load
    result = unpickler.load()
  File "/mnt/bwpy/single/usr/lib/python3.5/site-packages/torch/serialization.py", line 508, in persistent_load
    data_type(size), location)
  File "/mnt/bwpy/single/usr/lib/python3.5/site-packages/torch/serialization.py", line 104, in default_restore_location
    result = fn(storage, location)
  File "/mnt/bwpy/single/usr/lib/python3.5/site-packages/torch/serialization.py", line 86, in _cuda_deserialize
    return obj.cuda(device)
  File "/mnt/bwpy/single/usr/lib/python3.5/site-packages/torch/_utils.py", line 76, in _cuda
    return new_type(self.size()).copy_(self, non_blocking)
  File "/mnt/bwpy/single/usr/lib/python3.5/site-packages/torch/cuda/__init__.py", line 495, in _lazy_new
    return super(_CudaBase, cls).__new__(cls, *args, **kwargs)
RuntimeError: CUDA error: all CUDA-capable devices are busy or unavailable
Sun Oct 20 21:44:59 2019: [unset]:_pmi_alps_sync:alps response not OKAY
Sun Oct 20 21:44:59 2019: [unset]:_pmiu_daemon:_pmi_alps_sync failed 
Sun Oct 20 21:44:59 2019: [PE_0]:_pmi_daemon_barrier:PE pipe read failed from daemon errno = Success
Sun Oct 20 21:44:59 2019: [PE_0]:_pmi_init:_pmi_daemon_barrier returned -1
Traceback (most recent call last):
  File "RNN_test.py", line 50, in <module>
    model = torch.load('rnn.model')
  File "/mnt/bwpy/single/usr/lib/python3.5/site-packages/torch/serialization.py", line 358, in load
    return _load(f, map_location, pickle_module)
  File "/mnt/bwpy/single/usr/lib/python3.5/site-packages/torch/serialization.py", line 542, in _load
    result = unpickler.load()
  File "/mnt/bwpy/single/usr/lib/python3.5/site-packages/torch/serialization.py", line 508, in persistent_load
    data_type(size), location)
  File "/mnt/bwpy/single/usr/lib/python3.5/site-packages/torch/serialization.py", line 104, in default_restore_location
    result = fn(storage, location)
  File "/mnt/bwpy/single/usr/lib/python3.5/site-packages/torch/serialization.py", line 86, in _cuda_deserialize
    return obj.cuda(device)
  File "/mnt/bwpy/single/usr/lib/python3.5/site-packages/torch/_utils.py", line 76, in _cuda
    return new_type(self.size()).copy_(self, non_blocking)
  File "/mnt/bwpy/single/usr/lib/python3.5/site-packages/torch/cuda/__init__.py", line 495, in _lazy_new
    return super(_CudaBase, cls).__new__(cls, *args, **kwargs)
RuntimeError: CUDA error: all CUDA-capable devices are busy or unavailable
Sun Oct 20 21:58:56 2019: [unset]:_pmi_alps_sync:alps response not OKAY
Sun Oct 20 21:58:56 2019: [unset]:_pmiu_daemon:_pmi_alps_sync failed 
Sun Oct 20 21:58:56 2019: [PE_0]:_pmi_daemon_barrier:PE pipe read failed from daemon errno = Success
Sun Oct 20 21:58:56 2019: [PE_0]:_pmi_init:_pmi_daemon_barrier returned -1
Traceback (most recent call last):
  File "RNN_test.py", line 103, in <module>
    test_accu.append(epoch_acc)
NameError: name 'test_accu' is not defined
